Workbook

Sheet data
A1: ID number | B1: DATE | C1: HOUR | D1: Hour2 | E1: Day_moment | F1: STREET | G1: DISTRICT | H1: District_area | I1: ACCIDENT TYPE | J1: WEATHER | K1: PERSON | L1: AGE RANGE | M1: SEX | N1: LESIVITY
A2: 2019S018545 | B2: 43563 | C2: 0.51388889 | D2: =HOUR(C2) -> 12 | E2: =IF(D2<15,"Before 15","After 15") -> Before 15 | F2: AVDA. MANZANARES | G2: =VLOOKUP(F2,DISTRICTS!B$2:C$626,2,FALSE) -> USERA | H2: =IFERROR(VLOOKUP(G2,'areas for question 4'!A$2:B$10,2,FALSE),"") | I2: Hitting a person | J2: Cloudy | K2: Pedestrian | L2: FROM 0 TO 5 YEARS OLD | M2: Male | N2: 7
A3: 2019S021283 | B3: 43595 | C3: 0.48611111 | D3: =HOUR(C3) -> 11 | E3: =IF(D3<15,"Before 15","After 15") -> Before 15 | F3: MADRID RIO | G3: =VLOOKUP(F3,DISTRICTS!B$2:C$626,2,FALSE) -> CARABANCHEL | H3: =IFERROR(VLOOKUP(G3,'areas for question 4'!A$2:B$10,2,FALSE),"") | I3: Reach | J3: Clear | K3: Passenger | L3: FROM 0 TO 5 YEARS OLD | M3: Male | N3: 14
A4: 2019S023732 | B4: 43629 | C4: 0.89930556 | D4: =HOUR(C4) -> 21 | E4: =IF(D4<15,"Before 15","After 15") -> After 15 | F4: CALL. JACOMETREZO | G4: =VLOOKUP(F4,DISTRICTS!B$2:C$626,2,FALSE) -> CENTRO | H4: =IFERROR(VLOOKUP(G4,'areas for question 4'!A$2:B$10,2,FALSE),"") | I4: Hitting a person | J4: Clear | K4: Pedestrian | L4: FROM 0 TO 5 YEARS OLD | M4: Female | N4: 2
A5: 2019S026332 | B5: 43659 | C5: 0.91666667 | D5: =HOUR(C5) -> 22 | E5: =IF(D5<15,"Before 15","After 15") -> After 15 | F5: AVDA. MANZANARES / PQUE. MADRID RIO | G5: =VLOOKUP(F5,DISTRICTS!B$2:C$626,2,FALSE) -> CARABANCHEL | H5: =IFERROR(VLOOKUP(G5,'areas for question 4'!A$2:B$10,2,FALSE),"") | I5: Hitting a person | J5: Clear | K5: Pedestrian | L5: FROM 0 TO 5 YEARS OLD | M5: Male | N5: 1
A6: 2019S027484 | B6: 43663 | C6: 0.84027778 | D6: =HOUR(C6) -> 20 | E6: =IF(D6<15,"Before 15","After 15") -> After 15 | F6: PQUE. MADRID RIO, +00300E | G6: =VLOOKUP(F6,DISTRICTS!B$2:C$626,2,FALSE) -> LATINA | H6: =IFERROR(VLOOKUP(G6,'areas for question 4'!A$2:B$10,2,FALSE),"") | I6: Hitting a person | J6: Clear | K6: Pedestrian | L6: FROM 0 TO 5 YEARS OLD | M6: Male | N6: 7
A7: 2019S029101 | B7: 43706 | C7: 0.61458333 | D7: =HOUR(C7) -> 14 | E7: =IF(D7<15,"Before 15","After 15") -> Before 15 | F7: PASEO. ALBERTO PALACIOS | G7: =VLOOKUP(F7,DISTRICTS!B$2:C$626,2,FALSE) -> VILLAVERDE | H7: =IFERROR(VLOOKUP(G7,'areas for question 4'!A$2:B$10,2,FALSE),"") | I7: Hitting a person | J7: Clear | K7: Pedestrian | L7: FROM 0 TO 5 YEARS OLD | M7: Male | N7: 7
A8: 2019S029560 | B8: 43713 | C8: 0.80902778 | D8: =HOUR(C8) -> 19 | E8: =IF(D8<15,"Before 15","After 15") -> After 15 | F8: CALL. FRANCOS RODRIGUEZ | G8: =VLOOKUP(F8,DISTRICTS!B$2:C$626,2,FALSE) -> TETUÁN | H8: =IFERROR(VLOOKUP(G8,'areas for question 4'!A$2:B$10,2,FALSE),"") -> North | I8: Hitting a person | J8: Clear | K8: Pedestrian | L8: FROM 0 TO 5 YEARS OLD | M8: Male | N8: 7
A9: 2019S034766 | B9: 43761 | C9: 0.82638889 | D9: =HOUR(C9) -> 19 | E9: =IF(D9<15,"Before 15","After 15") -> After 15 | F9: AVDA. POBLADOS / CALL. CERILLERAS | G9: =VLOOKUP(F9,DISTRICTS!B$2:C$626,2,FALSE) -> CARABANCHEL | H9: =IFERROR(VLOOKUP(G9,'areas for question 4'!A$2:B$10,2,FALSE),"") | I9: Head-on collision | J9: Clear | K9: Driver | L9: FROM 0 TO 5 YEARS OLD | M9: Male | N9: 7
A10: 2019S036089 | B10: 43788 | C10: 0.38194444 | D10: =HOUR(C10) -> 9 | E10: =IF(D10<15,"Before 15","After 15") -> Before 15 | F10: CALL. MARTIN MUÑOZ DE LAS POSADAS | G10: =VLOOKUP(F10,DISTRICTS!B$2:C$626,2,FALSE) -> VILLA DE VALLECAS | H10: =IFERROR(VLOOKUP(G10,'areas for question 4'!A$2:B$10,2,FALSE),"") | I10: Lateral collision | J10: Clear | K10: Passenger | L10: FROM 0 TO 5 YEARS OLD | M10: Female | N10: 14
A11: 2019S039890 | B11: 43826 | C11: 0.77083333 | D11: =HOUR(C11) -> 18 | E11: =IF(D11<15,"Before 15","After 15") -> After 15 | F11: CALL. ALEJANDRO SANCHEZ | G11: =VLOOKUP(F11,DISTRICTS!B$2:C$626,2,FALSE) -> CARABANCHEL | H11: =IFERROR(VLOOKUP(G11,'areas for question 4'!A$2:B$10,2,FALSE),"") | I11: Hitting a person | J11: Unknown | K11: Pedestrian | L11: FROM 0 TO 5 YEARS OLD | M11: Male | N11: 7
A12: 2019S004939 | B12: 43486 | C12: 0.70138889 | D12: =HOUR(C12) -> 16 | E12: =IF(D12<15,"Before 15","After 15") -> After 15 | F12: CALL. SAN ENRIQUE DE OSSO | G12: =VLOOKUP(F12,DISTRICTS!B$2:C$626,2,FALSE) -> HORTALEZA | H12: =IFERROR(VLOOKUP(G12,'areas for question 4'!A$2:B$10,2,FALSE),"") | I12: Head-on collision | J12: Clear | K12: Driver | L12: FROM 10 TO 14 YEARS | M12: Male | N12: 2
A13: 2019S006655 | B13: 43495 | C13: 0.55555556 | D13: =HOUR(C13) -> 13 | E13: =IF(D13<15,"Before 15","After 15") -> Before 15 | F13: AVDA. CARABANCHEL ALTO | G13: =VLOOKUP(F13,DISTRICTS!B$2:C$626,2,FALSE) -> CARABANCHEL | H13: =IFERROR(VLOOKUP(G13,'areas for question 4'!A$2:B$10,2,FALSE),"") | I13: Head-on collision | J13: Clear | K13: Driver | L13: FROM 10 TO 14 YEARS | M13: Female | N13: 1
... A34: 2019S000045 | B34: 43468 | C34: 0.4375 | D34: =HOUR(C34) -> 10 | E34: =IF(D34<15,"Before 15","After 15") -> Before 15 | F34: CTRA. DEHESA DE LA VILLA | G34: =VLOOKUP(F34,DISTRICTS!B$2:C$626,2,FALSE) -> MONCLOA-ARAVACA | H34: =IFERROR(VLOOKUP(G34,'areas for question 4'!A$2:B$10,2,FALSE),"") | I34: Fall | J34: Clear | K34: Driver | L34: FROM 15 TO 17 YEARS | M34: Male | N34: 2
A35: 2019S001678 | B35: 43474 | C35: 0.53472222 | D35: =HOUR(C35) -> 12 | E35: =IF(D35<15,"Before 15","After 15") -> Before 15 | F35: CALL. GRAN VIA | G35: =VLOOKUP(F35,DISTRICTS!B$2:C$626,2,FALSE) -> CENTRO | H35: =IFERROR(VLOOKUP(G35,'areas for question 4'!A$2:B$10,2,FALSE),"") | I35: Reach | J35: Clear | K35: Driver | L35: FROM 15 TO 17 YEARS | M35: Male
A36: 2019S003364 | B36: 43477 | C36: 0.54375 | D36: =HOUR(C36) -> 13 | E36: =IF(D36<15,"Before 15","After 15") -> Before 15 | F36: AVDA. ENSANCHE DE VALLECAS | G36: =VLOOKUP(F36,DISTRICTS!B$2:C$626,2,FALSE) -> VILLA DE VALLECAS | H36: =IFERROR(VLOOKUP(G36,'areas for question 4'!A$2:B$10,2,FALSE),"") | I36: Head-on collision | J36: Unknown | K36: Driver | L36: FROM 15 TO 17 YEARS | M36: Female | N36: 7
A37: 2019S008448 | B37: 43502 | C37: 0.33680556 | D37: =HOUR(C37) -> 8 | E37: =IF(D37<15,"Before 15","After 15") -> Before 15 | F37: AVDA. LLANO CASTELLANO / AVDA. CARDENAL HERRERA ORIA | G37: =VLOOKUP(F37,DISTRICTS!B$2:C$626,2,FALSE) -> FUENCARRAL-EL PARDO | H37: =IFERROR(VLOOKUP(G37,'areas for question 4'!A$2:B$10,2,FALSE),"") -> North | I37: Hitting a person | J37: Clear | K37: Pedestrian | L37: FROM 15 TO 17 YEARS | M37: Female | N37: 7
A38: 2019S012142 | B38: 43516 | C38: 0.32291667 | D38: =HOUR(C38) -> 7 | E38: =IF(D38<15,"Before 15","After 15") -> Before 15 | F38: CALL. ATOCHA | G38: =VLOOKUP(F38,DISTRICTS!B$2:C$626,2,FALSE) -> CENTRO | H38: =IFERROR(VLOOKUP(G38,'areas for question 4'!A$2:B$10,2,FALSE),"") | I38: Fall | J38: Clear | K38: Driver | L38: FROM 15 TO 17 YEARS | M38: Female | N38: 7
A39: 2019S014016 | B39: 43525 | C39: 0.52083333 | D39: =HOUR(C39) -> 12 | E39: =IF(D39<15,"Before 15","After 15") -> Before 15 | F39: CALL. HACIENDA DE PAVONES / CALL. BRUJAS | G39: =VLOOKUP(F39,DISTRICTS!B$2:C$626,2,FALSE) -> MORATALAZ | H39: =IFERROR(VLOOKUP(G39,'areas for question 4'!A$2:B$10,2,FALSE),"") -> East | I39: Other | J39: Clear | K39: Driver | L39: FROM 15 TO 17 YEARS | M39: Male | N39: 7
A40: 2019S016088 | B40: 43534 | C40: 0.72638889 | D40: =HOUR(C40) -> 17 | E40: =IF(D40<15,"Before 15","After 15") -> After 15 | F40: AVDA. INGENIERO EMILIO HERRERA | G40: =VLOOKUP(F40,DISTRICTS!B$2:C$626,2,FALSE) -> HORTALEZA | H40: =IFERROR(VLOOKUP(G40,'areas for question 4'!A$2:B$10,2,FALSE),"") | I40: Head-on collision | J40: Clear | K40: Driver | L40: FROM 15 TO 17 YEARS | M40: Female | N40: 7
A41: 2019S016322 | B41: 43541 | C41: 0.42013889 | D41: =HOUR(C41) -> 10 | E41: =IF(D41<15,"Before 15","After 15") -> Before 15 | F41: CALL. SUECIA / AVDA. CANILLEJAS A VICALVARO | G41: =VLOOKUP(F41,DISTRICTS!B$2:C$626,2,FALSE) -> SAN BLAS-CANILLEJAS | H41: =IFERROR(VLOOKUP(G41,'areas for question 4'!A$2:B$10,2,FALSE),"") -> East | I41: Fall | J41: Clear | K41: Driver | L41: FROM 15 TO 17 YEARS | M41: Male | N41: 7
A42: 2019S017198 | B42: 43549 | C42: 0.5 | D42: =HOUR(C42) -> 12 | E42: =IF(D42<15,"Before 15","After 15") -> Before 15 | F42: CALL. PORTOMARIN | G42: =VLOOKUP(F42,DISTRICTS!B$2:C$626,2,FALSE) -> FUENCARRAL-EL PARDO | H42: =IFERROR(VLOOKUP(G42,'areas for question 4'!A$2:B$10,2,FALSE),"") -> North | I42: Fall | J42: Clear | K42: Driver | L42: FROM 15 TO 17 YEARS | M42: Male | N42: 5
A43: 2019S017718 | B43: 43555 | C43: 0.51041667 | D43: =HOUR(C43) -> 12 | E43: =IF(D43<15,"Before 15","After 15") -> Before 15 | F43: PASEO. CASTELLANA | G43: =VLOOKUP(F43,DISTRICTS!B$2:C$626,2,FALSE) -> CHAMARTÍN | H43: =IFERROR(VLOOKUP(G43,'areas for question 4'!A$2:B$10,2,FALSE),"") -> North | I43: Fall | J43: Light rain | K43: Driver | L43: FROM 15 TO 17 YEARS | M43: Male | N43: 7
A44: 2019S018345 | B44: 43563 | C44: 0.63541667 | D44: =HOUR(C44) -> 15 | E44: =IF(D44<15,"Before 15","After 15") -> After 15 | F44: CALL. DOBLA / AVDA. POBLADOS | G44: =VLOOKUP(F44,DISTRICTS!B$2:C$626,2,FALSE) -> CARABANCHEL | H44: =IFERROR(VLOOKUP(G44,'areas for question 4'!A$2:B$10,2,FALSE),"") | I44: Lateral collision | J44: Clear | K44: Driver | L44: FROM 15 TO 17 YEARS | M44: Male | N44: 7
A45: 2019S018656 | B45: 43566 | C45: 0.66666667 | D45: =HOUR(C45) -> 16 | E45: =IF(D45<15,"Before 15","After 15") -> After 15 | F45: CALL. LUCHANA | G45: =VLOOKUP(F45,DISTRICTS!B$2:C$626,2,FALSE) -> CHAMBERÍ | H45: =IFERROR(VLOOKUP(G45,'areas for question 4'!A$2:B$10,2,FALSE),"") -> North | I45: Fall | J45: Clear | K45: Driver | L45: FROM 15 TO 17 YEARS | M45: Male | N45: 6
A46: 2019S020579 | B46: 43592 | C46: 0.63194444 | D46: =HOUR(C46) -> 15 | E46: =IF(D46<15,"Before 15","After 15") -> After 15 | F46: CALL. ALCALA | G46: =VLOOKUP(F46,DISTRICTS!B$2:C$626,2,FALSE) -> CENTRO | H46: =IFERROR(VLOOKUP(G46,'areas for question 4'!A$2:B$10,2,FALSE),"") | I46: Reach | J46: Clear | K46: Driver | L46: FROM 15 TO 17 YEARS | M46: Male | N46: 14
A47: 2019S020923 | B47: 43597 | C47: 0.85416667 | D47: =HOUR(C47) -> 20 | E47: =IF(D47<15,"Before 15","After 15") -> After 15 | F47: CALL. MARQUES DE VIANA | G47: =VLOOKUP(F47,DISTRICTS!B$2:C$626,2,FALSE) -> TETUÁN | H47: =IFERROR(VLOOKUP(G47,'areas for question 4'!A$2:B$10,2,FALSE),"") -> North | I47: Lateral collision | J47: Clear | K47: Driver | L47: FROM 15 TO 17 YEARS | M47: Male | N47: 7
... A78: 2019S022707 | B78: 43617 | C78: 0.95833333 | D78: =HOUR(C78) -> 23 | E78: =IF(D78<15,"Before 15","After 15") -> After 15 | F78: AVDA. ASTURIAS | G78: =VLOOKUP(F78,DISTRICTS!B$2:C$626,2,FALSE) -> TETUÁN | H78: =IFERROR(VLOOKUP(G78,'areas for question 4'!A$2:B$10,2,FALSE),"") -> North | I78: Fall | J78: Clear | K78: Driver | L78: 18 TO 20 YEARS | M78: Male | N78: 6
A79: 2019S022622 | B79: 43617 | C79: 0.12152778 | D79: =HOUR(C79) -> 2 | E79: =IF(D79<15,"Before 15","After 15") -> Before 15 | F79: AVDA. ASTURIAS / CALL. VIA LIMITE | G79: =VLOOKUP(F79,DISTRICTS!B$2:C$626,2,FALSE) -> TETUÁN | H79: =IFERROR(VLOOKUP(G79,'areas for question 4'!A$2:B$10,2,FALSE),"") -> North | I79: Head-on collision | J79: Clear | K79: Driver | L79: 18 TO 20 YEARS | M79: Male
A80: 2019S023497 | B80: 43623 | C80: 0.83680556 | D80: =HOUR(C80) -> 20 | E80: =IF(D80<15,"Before 15","After 15") -> After 15 | F80: CALL. JAVIER DE MIGUEL | G80: =VLOOKUP(F80,DISTRICTS!B$2:C$626,2,FALSE) -> PUENTE DE VALLECAS | H80: =IFERROR(VLOOKUP(G80,'areas for question 4'!A$2:B$10,2,FALSE),"") | I80: Fall | J80: Clear | K80: Driver | L80: 18 TO 20 YEARS | M80: Male | N80: 3
A81: 2019S023601 | B81: 43627 | C81: 0.81805556 | D81: =HOUR(C81) -> 19 | E81: =IF(D81<15,"Before 15","After 15") -> After 15 | F81: CALL. GENERAL LACY / CALL. ANCORA | G81: =VLOOKUP(F81,DISTRICTS!B$2:C$626,2,FALSE) -> ARGANZUELA | H81: =IFERROR(VLOOKUP(G81,'areas for question 4'!A$2:B$10,2,FALSE),"") | I81: Head-on collision | J81: Clear | K81: Driver | L81: 18 TO 20 YEARS | M81: Male | N81: 1
A82: 2019S024149 | B82: 43629 | C82: 0.85972222 | D82: =HOUR(C82) -> 20 | E82: =IF(D82<15,"Before 15","After 15") -> After 15 | F82: AVDA. MONASTERIO DE SILOS | G82: =VLOOKUP(F82,DISTRICTS!B$2:C$626,2,FALSE) -> FUENCARRAL-EL PARDO | H82: =IFERROR(VLOOKUP(G82,'areas for question 4'!A$2:B$10,2,FALSE),"") -> North | I82: Fall | J82: Clear | K82: Driver | L82: 18 TO 20 YEARS | M82: Male | N82: 2
A83: 2019S023734 | B83: 43629 | C83: 0.85763889 | D83: =HOUR(C83) -> 20 | E83: =IF(D83<15,"Before 15","After 15") -> After 15 | F83: GTA. SANTUARIO DE TISCAR | G83: =VLOOKUP(F83,DISTRICTS!B$2:C$626,2,FALSE) -> FUENCARRAL-EL PARDO | H83: =IFERROR(VLOOKUP(G83,'areas for question 4'!A$2:B$10,2,FALSE),"") -> North | I83: Crash into fixed obstacle | J83: Clear | K83: Driver | L83: 18 TO 20 YEARS | M83: Male | N83: 2
A84: 2019S023783 | B84: 43630 | C84: 0.010416667 | D84: =HOUR(C84) -> 0 | E84: =IF(D84<15,"Before 15","After 15") -> Before 15 | F84: GTA. RUIZ JIMENEZ / CALL. SAN BERNARDO | G84: =VLOOKUP(F84,DISTRICTS!B$2:C$626,2,FALSE) -> CENTRO | H84: =IFERROR(VLOOKUP(G84,'areas for question 4'!A$2:B$10,2,FALSE),"") | I84: Lateral collision | J84: Clear | K84: Driver | L84: 18 TO 20 YEARS | M84: Male | N84: 1
A85: 2019S025170 | B85: 43645 | C85: 0.69791667 | D85: =HOUR(C85) -> 16 | E85: =IF(D85<15,"Before 15","After 15") -> After 15 | F85: CALL. GENERAL RICARDOS | G85: =VLOOKUP(F85,DISTRICTS!B$2:C$626,2,FALSE) -> CARABANCHEL | H85: =IFERROR(VLOOKUP(G85,'areas for question 4'!A$2:B$10,2,FALSE),"") | I85: Hitting a person | J85: Clear | K85: Driver | L85: 18 TO 20 YEARS | M85: Male | N85: 14
A86: 2019S025348 | B86: 43648 | C86: 0.38888889 | D86: =HOUR(C86) -> 9 | E86: =IF(D86<15,"Before 15","After 15") -> Before 15 | F86: CTRA. RODAJOS | G86: =VLOOKUP(F86,DISTRICTS!B$2:C$626,2,FALSE) -> MONCLOA-ARAVACA | H86: =IFERROR(VLOOKUP(G86,'areas for question 4'!A$2:B$10,2,FALSE),"") | I86: Hitting a person | J86: Clear | K86: Pedestrian | L86: 18 TO 20 YEARS | M86: Male | N86: 14
A87: 2019S025555 | B87: 43650 | C87: 0.86458333 | D87: =HOUR(C87) -> 20 | E87: =IF(D87<15,"Before 15","After 15") -> After 15 | F87: CALL. CLAUDIO COELLO | G87: =VLOOKUP(F87,DISTRICTS!B$2:C$626,2,FALSE) -> SALAMANCA | H87: =IFERROR(VLOOKUP(G87,'areas for question 4'!A$2:B$10,2,FALSE),"") | I87: Head-on collision | J87: Clear | K87: Driver | L87: 18 TO 20 YEARS | M87: Male | N87: 6
A88: 2019S025769 | B88: 43653 | C88: 0.8125 | D88: =HOUR(C88) -> 19 | E88: =IF(D88<15,"Before 15","After 15") -> After 15 | F88: CALL. CERRO DE LA PLATA | G88: =VLOOKUP(F88,DISTRICTS!B$2:C$626,2,FALSE) -> RETIRO | H88: =IFERROR(VLOOKUP(G88,'areas for question 4'!A$2:B$10,2,FALSE),"") | I88: Crash into fixed obstacle | J88: Clear | K88: Driver | L88: 18 TO 20 YEARS | M88: Male | N88: 2
A89: 2019S026237 | B89: 43658 | C89: 0.57291667 | D89: =HOUR(C89) -> 13 | E89: =IF(D89<15,"Before 15","After 15") -> Before 15 | F89: CALL. RESINA | G89: =VLOOKUP(F89,DISTRICTS!B$2:C$626,2,FALSE) -> VILLAVERDE | H89: =IFERROR(VLOOKUP(G89,'areas for question 4'!A$2:B$10,2,FALSE),"") | I89: Head-on collision | J89: Clear | K89: Driver | L89: 18 TO 20 YEARS | M89: Male | N89: 5
A90: 2019S027182 | B90: 43672 | C90: 0.90625 | D90: =HOUR(C90) -> 21 | E90: =IF(D90<15,"Before 15","After 15") -> After 15 | F90: CALL. AZUCENAS | G90: =VLOOKUP(F90,DISTRICTS!B$2:C$626,2,FALSE) -> TETUÁN | H90: =IFERROR(VLOOKUP(G90,'areas for question 4'!A$2:B$10,2,FALSE),"") -> North | I90: Head-on collision | J90: Clear | K90: Driver | L90: 18 TO 20 YEARS | M90: Male | N90: 2
...

Sheet 1
A2: % of increase | B2: Gender
A3: Months | B3: Female | C3: Male
A4: ene
A5: feb | B5: 1.2857143 | C5: -0.16666667 | E5: Differences of sign in several months (Feb, Jun, Oct ..)
A6: mar | B6: 0.375 | C6: 0.71428571
A7: abr | B7: -0.54545455 | C7: -0.36666667
A8: may | B8: 1.6 | C8: 0.71052632
A9: jun | B9: -0.15384615 | C9: 0.12307692
A10: jul | B10: 0 | C10: -0.12328767
A11: ago | B11: -0.45454545 | C11: -0.3125
A12: sep | B12: 1.25 | C12: 0.90909091
A13: oct | B13: 0.037037037 | C13: -0.1547619
A14: nov | B14: -0.32142857 | C14: -0.4084507
A15: dic | B15: -0.26315789 | C15: -0.21428571
A16: Grand Total

Sheet 2
A1: DISTRICT | B1: (Multiple Items)
A3: % of accidents | B3: Type of accident
A4: Age Range | B4: Crash into fixed obstacle | C4: Fall | D4: Head-on collision | E4: Hitting a person | F4: Lateral collision | G4: Other | H4: Reach
A5: LESS THAN 18 YEARS OLD | B5: 0.5 | C5: 0.15384615 | D5: 0.29411765 | E5: 0.28571429 | F5: 0.28571429 | G5: 0 | H5: 0.11111111
A6: From 18 to 29 | B6: 0.25 | C6: 0.23076923 | D6: 0.29411765 | E6: 0.14285714 | F6: 0 | G6: 0 | H6: 0.22222222
A7: From 30 to 39 | B7: 0.25 | C7: 0.23076923 | D7: 0.11764706 | E7: 0.095238095 | F7: 0.28571429 | G7: 0 | H7: 0.22222222
A8: From 40 to 49 | B8: 0 | C8: 0.30769231 | D8: 0.11764706 | E8: 0.14285714 | F8: 0 | G8: 1 | H8: 0.11111111
A9: From 50 to 59 | B9: 0 | C9: 0.076923077 | D9: 0 | E9: 0.19047619 | F9: 0.28571429 | G9: 0 | H9: 0.22222222
A10: 60 or more | B10: 0 | C10: 0 | D10: 0.17647059 | E10: 0.14285714 | F10: 0.14285714 | G10: 0 | H10: 0.11111111
A11: Grand Total | B11: 1 | C11: 1 | D11: 1 | E11: 1 | F11: 1 | G11: 1 | H11: 1
B13: NOTE: AGE RANGES ARE GROUPED
B15: The majority of accidents are normally on the younger age range, probably because they are the ones that rent bikes more frequently
B16: However, for some type of accidents, this is not entirely true: Fall, Lateral collision, Other or Reach

Sheet 3
A2: % of accidents | B2: Moment of the day
A3: Row Labels | B3: Before 15 | C3: After 15
A4: ARGANZUELA | B4: 0.46753247 | C4: 0.53246753
A5: BARAJAS | B5: 0.46153846 | C5: 0.53846154
A6: CARABANCHEL | B6: 0.46666667 | C6: 0.53333333
A7: CENTRO | B7: 0.40384615 | C7: 0.59615385
A8: CHAMARTÍN | B8: 0.44230769 | C8: 0.55769231
A9: CHAMBERÍ | B9: 0.33846154 | C9: 0.66153846
A10: CIUDAD LINEAL | B10: 0.42307692 | C10: 0.57692308
A11: FUENCARRAL-EL PARDO | B11: 0.67346939 | C11: 0.32653061
A12: HORTALEZA | B12: 0.33333333 | C12: 0.66666667
A13: LATINA | B13: 0.43333333 | C13: 0.56666667
A14: MONCLOA-ARAVACA | B14: 0.37777778 | C14: 0.62222222
A15: MORATALAZ | B15: 0.40740741 | C15: 0.59259259
... A25: Grand Total | B25: 0.46179775 | C25: 0.53820225

Sheet areas for question 4
A1: DISTRICT | B1: AREA
A2: CIUDAD LINEAL | B2: East
A3: MORATALAZ | B3: East
A4: SAN BLAS-CANILLEJAS | B4: East
A5: VICÁLVARO | B5: East
A6: BARAJAS | B6: East
A7: CHAMARTÍN | B7: North
A8: FUENCARRAL-EL PARDO | B8: North
A9: TETUÁN | B9: North
A10: CHAMBERÍ | B10: North

Sheet 4
A3: Average of LESIVITY | B3: Column Labels
A4: Row Labels | B4: East | C4: North
A5: Clear | B5: 6.4285714 | C5: 6.3090909
A6: Cloudy | B6: 4.3333333 | C6: 5.5 | E6: Differences in most weather conditions
A7: Hailing | B7: 7
A8: Heavy rain | B8: 7
A9: Light rain | B9: 4.8 | C9: 6.2666667
A10: Grand Total | B10: 6.2758621 | C10: 6.2880435

Sheet DISTRICTS
B1: STREET | C1: DISTRICT
B2: CALL. BATALLA DEL SALADO / CALL. CACERES | C2: ARGANZUELA
B3: CALL. EMBAJADORES | C3: ARGANZUELA
B4: CALL. EMBAJADORES / CALL. LABRADORES | C4: ARGANZUELA
B5: CALL. EMBAJADORES / CALL. RICARDO GOIZUETA | C5: ARGANZUELA
B6: CALL. GENERAL LACY / CALL. ANCORA | C6: ARGANZUELA
B7: CALL. JUAN DE MARIANA | C7: ARGANZUELA
B8: CALL. JUAN DUQUE / CALL. MORENO NIETO | C8: ARGANZUELA
B9: CALL. MANZANARES / CALL. LINNEO | C9: ARGANZUELA
B10: CALL. MENDEZ ALVARO / AVDA. PLANETARIO | C10: ARGANZUELA
B11: CALL. MENDEZ ALVARO / CALL. TITAN | C11: ARGANZUELA
B12: CALL. MIGUEL ARREDONDO / CALL. ALONSO CARBONELL | C12: ARGANZUELA
... B626: SENDA CICLABLE-AV.ROSALES-CARRET.VILLAV. A VALLECA | C626: VILLAVERDE
